Workbook

Sheet REQUI P2141
D1: INSTITUTO POBLANO DE LOS PUEBLOS INDÍGENAS | H1: FORMATO DE REQUISICIÓN
D2: DIRECCIÓN DE ADMINISTRACIÓN Y FINANZAS | H2: No.
D3: DEPARTAMENTO DE RECURSOS MATERIALES Y SERVICIOS GENERALES
H4: FECHA: | J4: =TODAY() -> 46307
A6: DIRECCIÓN O UNIDAD SOLICITANTE: | E6: SUBDIRECCIÓN DE DESARROLLO DE TECNOLOGÍAS DE LA INFORMACIÓN
A7: RESPONSABLE DE LA DIRECCIÓN: | E7: MIGUEL TRINIDAD GÓMEZ HERNÁNDEZ
A8: PARTIDA PRESUPUESTAL-OBJETO DE GASTO: | E8: 2141 | G8: UR: | I8: 169
A9: PRESUPUESTO: | E9: 32527.48 | G9: COMPONENTE: | I9: C3 | M9: TOTAL | N9: + IVA
A10: FECHA PARA CUANDO SE REQUIERE: | E10: 46328 | G10: ACTIVIDAD: | I10: A9 | M10: =SUM(N13:N30) -> 27639.56 | N10: =M10*1.16 -> 32061.89
A12: No. | B12: DESCRIPCIÓN DEL BIEN Y/O SERVICIO | H12: UNIDAD DE MEDIDA | J12: CANTIDAD SOLICITADA | M12: PRECIOS | N12: SUB TOTAL | O12: LINKS
A13: 1 | B13: ='P2141'!A3 -> REXQualis Completo Kit Compatible C/ Arduino IDE Con Español Tutorial, Placa R3,Placa de pruebas 830, 120 resistencias y otros módulos diversos. | H13: ='P2141'!B3 -> KIT | J13: ='P2141'!C3 -> 10 | M13: ='P2141'!E3 -> 764.9 | N13: =J13*M13 -> 7649 | O13: ='P2141'!H3 -> https://www.mercadolibre.com.mx/rexqualis-completo-kit-compatible-c-arduino-ide-con-espanol-tutorial-placa-r3placa-de-pruebas-830-120-resistencias-y-otros-modulos-diversos/p/MLM37729310?pdp_filters=item_id%3AMLM5450691438&sid=purchases
A14: =+A13+1 -> 2 | B14: ='P2141'!A4 -> Sensor de temperatura encapsulado | H14: ='P2141'!B4 -> KIT | J14: ='P2141'!C4 -> 5 | M14: ='P2141'!E4 -> 97 | N14: =J14*M14 -> 485 | O14: ='P2141'!H4 -> https://www.mercadolibre.com.mx/kit-de-500-piezas-de-diodos-led-difusos-de-5-mm-para-proyectos-de-bricolaje-ideales-para-placas-pcb-circuitos-electronicos-de-baja-tension-e-indicadores-luminosos/p/MLM50109429?pdp_filters=item_id:MLM3696919158#is_advertising=true&searchVariation=MLM50109429&backend_model=search-backend&be_origin=backend&position=4&search_layout=grid&type=pad&tracking_id=3a63a533-eb22-4edb-a9a4-fb56e35e3817&ad_domain=VQCATCORE_LST&ad_position=4&ad_click_id=Yjc3NGUwNzgtODY5Zi00M2NkLTkxNTgtM2I3NDRmMGM0MjQw
A15: =+A14+1 -> 3 | B15: ='P2141'!A5 -> Buzzer Zumbador Piezoeléctrico 95db | H15: ='P2141'!B5 -> PZA | J15: ='P2141'!C5 -> 5 | M15: ='P2141'!E5 -> 198.99 | N15: =J15*M15 -> 994.95 | O15: ='P2141'!H5 -> https://www.mercadolibre.com.mx/10-piezas-sfm20b-324v-buzzer-zumbador-piezoelectrico-95db/up/MLMU3367610229?pdp_filters=item_id:MLM3963501926#is_advertising=true&searchVariation=MLMU3367610229&backend_model=search-backend&be_origin=backend&position=2&search_layout=grid&type=pad&tracking_id=ff70f396-c103-4885-9627-5bee64008741&ad_domain=VQCATCORE_LST&ad_position=2&ad_click_id=OTUxODljYWMtNTVjNy00MTExLWFmODgtNjgyZjljNjllMzU0
A16: =+A15+1 -> 4 | B16: ='P2141'!A6 -> Resistencia de carbon 1/2W 330 Ohms | H16: ='P2141'!B6 -> KIT | J16: ='P2141'!C6 -> 3 | M16: ='P2141'!E6 -> 211.68 | N16: =J16*M16 -> 635.04 | O16: ='P2141'!H6 -> https://www.mercadolibre.com.mx/kit-de-resistencias-2600-pzs-130-valores-14w-1/p/MLM46826035?pdp_filters=item_id:MLM5542915998#reviews
A17: =+A16+1 -> 5 | B17: ='P2141'!A7 -> Llantas para proyectos | H17: ='P2141'!B7 -> KIT | J17: ='P2141'!C7 -> 10 | M17: ='P2141'!E7 -> 49 | N17: =J17*M17 -> 490 | O17: ='P2141'!H7 -> https://www.steren.com.mx/llantas-de-plastico.html
A18: =+A17+1 -> 6 | B18: ='P2141'!A8 -> Paquete De 100 Fotorresistencias Ldr 5 Mm Sensor De Luz 5516 Tecneu | H18: ='P2141'!B8 -> PZA | J18: ='P2141'!C8 -> 2 | M18: ='P2141'!E8 -> 134.09 | N18: =J18*M18 -> 268.18 | O18: ='P2141'!H8 -> https://www.mercadolibre.com.mx/paquete-de-100-fotorresistencias-ldr-5-mm-sensor-de-luz-5516-tecneu/p/MLM50938693#polycard_client=search-desktop&be_origin=backend&overlay_label=not_apply&search_layout=grid&position=4&type=product&tracking_id=38756c6a-d6cd-48be-9f4a-f5048395610f&wid=MLM3730253870&sid=search
A19: =+A18+1 -> 7 | B19: ='P2141'!A9 -> Micro Switch Push 4 terminales 12V | H19: ='P2141'!B9 -> KIT | J19: ='P2141'!C9 -> 3 | M19: ='P2141'!E9 -> 96 | N19: =J19*M19 -> 288 | O19: ='P2141'!H9 -> https://www.mercadolibre.com.mx/kit-de-180-push-button-boton-4-pines-10-tamanos-switch-caja/up/MLMU710903762?pdp_filters=item_id:MLM2085754367#polycard_client=recommendations_vip-pads-up&reco_backend=recomm_platform_base_pads_ron_MERGE_marketplace&reco_model=recos_backend_only&reco_client=vip-pads-up&reco_item_pos=2&reco_backend_type=low_level&reco_id=0803ace9-cd71-446f-9dcf-202bcf15fa48&wid=MLM2085754367&sid=recos&is_advertising=true&ad_domain=VIPDESKTOP_UP&ad_position=3&ad_click_id=ZTQyNTNmZjItYjJlNy00MGI4LWE1OGQtYzkwYjU3OWU3YTFj
A20: =+A19+1 -> 8 | B20: ='P2141'!A10 -> Pila Alcalina de 9 V Alta capacidad | H20: ='P2141'!B10 -> PZA | J20: ='P2141'!C10 -> 20 | M20: ='P2141'!E10 -> 59 | N20: =J20*M20 -> 1180 | O20: ='P2141'!H10 -> https://www.steren.com.mx/pila-alcalina-ultra-9v-cuadrada-de-larga-duracion.html
A21: =+A20+1 -> 9 | B21: ='P2141'!A11 -> Multimetro Digital Basico | H21: ='P2141'!B11 -> PZA | J21: ='P2141'!C11 -> 10 | M21: ='P2141'!E11 -> 99.01 | N21: =J21*M21 -> 990.1 | O21: ='P2141'!H11 -> https://www.steren.com.mx/multimetro-compacto-economico.html
A22: =+A21+1 -> 10 | B22: ='P2141'!A12 -> Motorreductor Recto 48:1 Motor | H22: ='P2141'!B12 -> PZA | J22: ='P2141'!C12 -> 5 | M22: ='P2141'!E12 -> 258.81 | N22: =J22*M22 -> 1294.05 | O22: ='P2141'!H12 -> https://www.mercadolibre.com.mx/20-pzas-motorreductor-recto-481-motor-2-ejes-arduino/up/MLMU2982455006#polycard_client=search-desktop&be_origin=backend&overlay_label=not_apply&search_layout=grid&position=5&type=product&tracking_id=29515c33-b03d-4c80-915e-0d2167729923&wid=MLM3541658230&sid=search
A23: =+A22+1 -> 11 | B23: ='P2141'!A13 -> Servomotor Practinet SG90 Micro Servo 1.8kgcm Arduino Raspberry | H23: ='P2141'!B13 -> PZA | J23: ='P2141'!C13 -> 30 | M23: ='P2141'!E13 -> 89 | N23: =J23*M23 -> 2670 | O23: ='P2141'!H13 -> https://www.mercadolibre.com.mx/servomotor-practinet-sg90-micro-servo-18kgcm-arduino-raspberry/p/MLM46839997?pdp_filters=item_id:MLM5841824004#is_advertising=true&searchVariation=MLM46839997&backend_model=search-backend&be_origin=backend&position=19&search_layout=grid&type=pad&tracking_id=1b07fee3-cc47-473e-8060-7d9967da6741&ad_domain=VQCATCORE_LST&ad_position=19&ad_click_id=ZTI1ZWUwNzItNzg3My00ZWMwLWJkYjAtYjMyYTU4NzEwOTUw
A24: =+A22+1 -> 11 | B24: ='P2141'!A14 -> Sensor Ultrasonico Hc-sr04 Arduino | H24: ='P2141'!B14 -> PZA | J24: ='P2141'!C14 -> 15 | M24: ='P2141'!E14 -> 69 | N24: =J24*M24 -> 1035 | O24: ='P2141'!H14 -> https://www.mercadolibre.com.mx/sensor-ultrasonico-hc-sr04-arduino/p/MLM46959601
A25: =+A24+1 -> 12 | B25: ='P2141'!A15 -> 5 Piezas Sensor De Temperatura Tmp36 | H25: ='P2141'!B15 -> PZA | J25: ='P2141'!C15 -> 10 | M25: ='P2141'!E15 -> 102.92 | N25: =J25*M25 -> 1029.2 | O25: ='P2141'!H15 -> https://www.mercadolibre.com.mx/5-piezas-sensor-de-temperatura-tmp36/up/MLMU560815146?pdp_filters=item_id:MLM1584118283
A26: =+A25+1 -> 13 | B26: ='P2141'!A16 -> Display Lcd 16x2, 1602a Para Arduino, Con Pines Soladados | H26: ='P2141'!B16 -> PZA | J26: ='P2141'!C16 -> 10 | M26: ='P2141'!E16 -> 65 | N26: =J26*M26 -> 650 | O26: ='P2141'!H16 -> https://www.mercadolibre.com.mx/display-lcd-16x2-1602a-para-arduino-con-pines-soladados/up/MLMU532097588?pdp_filters=item_id:MLM814723036
A27: =+A26+1 -> 14 | B27: ='P2141'!A17 -> Transistor 2n2222a, Npn, Bipolar, (50 Piezas) | H27: ='P2141'!B17 -> PZA | J27: ='P2141'!C17 -> 10 | M27: ='P2141'!E17 -> 79 | N27: =J27*M27 -> 790 | O27: ='P2141'!H17 -> https://www.mercadolibre.com.mx/transistor-2n2222a-npn-bipolar-50-piezas/p/MLM2109649633?pdp_filters=item_id:MLM630938028
A28: =+A27+1 -> 15 | B28: ='P2141'!A18 -> Nobreak Enson ENS-EA2150 1500VA 900W 6 Contactos Negro Senoidal | H28: ='P2141'!B18 -> PZA | J28: ='P2141'!C18 -> 2 | M28: ='P2141'!E18 -> 3015 | N28: =J28*M28 -> 6030 | O28: ='P2141'!H18 -> https://www.mercadolibre.com.mx/nobreak-enson-ens-ea2150-1500va-900w-6-contactos-negro-senoidal/p/MLM25477014#reviews
A29: 16 | B29: ='P2141'!A19 -> Cable Extensión Usb 2.0 10 Metros Macho - Hembra Negro | H29: ='P2141'!B19 -> PZA | J29: ='P2141'!C19 -> 2 | M29: ='P2141'!E19 -> 217.43 | N29: =J29*M29 -> 434.86 | O29: ='P2141'!H19 -> https://www.mercadolibre.com.mx/cable-extension-usb-20--10-metros-macho--hembra-negro/up/MLMU3319157753#polycard_client=search-desktop&be_origin=backend&overlay_label=not_apply&search_layout=grid&position=5&type=product&tracking_id=fa282d6f-b1ee-4226-82f0-3655a52d9037&wid=MLM3861463798&sid=search
A30: 17 | B30: ='P2141'!A20 -> Adeske Kit de Limpieza para PC Soplador de Aire Inalámbrico 300000 RPM 4 Velocidades 4 Boquillas 10 Cepillos Batería 8000mAh Recargable Luz LED Pantalla LED | H30: ='P2141'!B20 -> PZA | J30: ='P2141'!C20 -> 2 | M30: ='P2141'!E20 -> 363.09 | N30: =J30*M30 -> 726.18 | O30: ='P2141'!H20 -> https://www.mercadolibre.com.mx/adeske-kit-de-limpieza-para-pc-soplador-de-aire-inalambrico-300000-rpm-4-velocidades-4-boquillas-10-cepillos-bateria-8000mah-recargable-luz-led-pantalla-led/p/MLM75893733?pdp_filters=item_id:MLM5847120474#is_advertising=true&searchVariation=MLM75893733&backend_model=search-backend&be_origin=backend&position=4&search_layout=grid&type=pad&tracking_id=1f9f0d86-6c56-4673-b889-9d8669b82c4a&ad_domain=VQCATCORE_LST&ad_position=4&ad_click_id=MjkxYWIzZmQtOWVlZC00NzgwLWE5OTYtMTVmZDNhYWQ1Yjkx
A32: JUSTIFICACIÓN: | D32: Materiales, útiles y equipos menores de tecnologías de la información y comunicaciones, para la implementación de cursos en Introducción a la Electrónica con Arduino, Sensores y Actuadores en Módulos de Apropiación Digital con Identidad. | H32: AUTORIZACION DIRECCION GENERAL
A35: ELABORÓ | C35: NOMBRE: | D35: MIGUEL TRINIDAD GÓMEZ HERNÁNDEZ
A36: Y SOLICITÓ | C36: AREA: | D36: SUBDIRECCIÓN DE DESARROLLO DE TECNOLOGÍAS DE LA INFORMACIÓN
A37: Vo. Bo. | C37: NOMBRE: | D37: YAIR OROPEZA RAMOS
C38: AREA: | D38: DEPARTAMENTO DE RECURSOS MATERIALES Y SERVICIOS GENERALES
A39: AUTORIZÓ | C39: NOMBRE: | D39: APOLINARIA MARTÍNEZ ARROYO
C40: AREA: | D40: DIRECTORA GENERAL DEL INSTITUTO POBLANO DE LOS PUEBLOS INDÍGENAS

Sheet P2141
E1: =SUM(Tabla1[Total]) -> 27639.56 | F1: =E1*1.16 -> 32061.89
A2: Descripción | B2: UM | C2: Cantidad | D2: Diseño | E2: Precio Público | F2: Proveedor Referencia | G2: Imagen Referencia | H2: Liga de referencia | I2: Total
A3: REXQualis Completo Kit Compatible C/ Arduino IDE Con Español Tutorial, Placa R3,Placa de pruebas 830, 120 resistencias y otros módulos diversos. | B3: KIT | C3: 10 | E3: 764.9 | F3: Mercado Libre | H3: https://www.mercadolibre.com.mx/rexqualis-completo-kit-compatible-c-arduino-ide-con-espanol-tutorial-placa-r3placa-de-pruebas-830-120-resistencias-y-otros-modulos-diversos/p/MLM37729310?pdp_filters=item_id%3AMLM5450691438&sid=purchases | I3: =E3*C3 -> 7649
A4: Sensor de temperatura encapsulado | B4: KIT | C4: 5 | E4: 97 | F4: Mercado Libre | H4: https://www.mercadolibre.com.mx/kit-de-500-piezas-de-diodos-led-difusos-de-5-mm-para-proyectos-de-bricolaje-ideales-para-placas-pcb-circuitos-electronicos-de-baja-tension-e-indicadores-luminosos/p/MLM50109429?pdp_filters=item_id:MLM3696919158#is_advertising=true&searchVariation=MLM50109429&backend_model=search-backend&be_origin=backend&position=4&search_layout=grid&type=pad&tracking_id=3a63a533-eb22-4edb-a9a4-fb56e35e3817&ad_domain=VQCATCORE_LST&ad_position=4&ad_click_id=Yjc3NGUwNzgtODY5Zi00M2NkLTkxNTgtM2I3NDRmMGM0MjQw | I4: =E4*C4 -> 485
A5: Buzzer Zumbador Piezoeléctrico 95db | B5: PZA | C5: 5 | E5: 198.99 | F5: Mercado Libre | H5: https://www.mercadolibre.com.mx/10-piezas-sfm20b-324v-buzzer-zumbador-piezoelectrico-95db/up/MLMU3367610229?pdp_filters=item_id:MLM3963501926#is_advertising=true&searchVariation=MLMU3367610229&backend_model=search-backend&be_origin=backend&position=2&search_layout=grid&type=pad&tracking_id=ff70f396-c103-4885-9627-5bee64008741&ad_domain=VQCATCORE_LST&ad_position=2&ad_click_id=OTUxODljYWMtNTVjNy00MTExLWFmODgtNjgyZjljNjllMzU0 | I5: =E5*C5 -> 994.95
A6: Resistencia de carbon 1/2W 330 Ohms | B6: KIT | C6: 3 | E6: 211.68 | F6: Mercado Libre | H6: https://www.mercadolibre.com.mx/kit-de-resistencias-2600-pzs-130-valores-14w-1/p/MLM46826035?pdp_filters=item_id:MLM5542915998#reviews | I6: =E6*C6 -> 635.04
A7: Llantas para proyectos | B7: KIT | C7: 10 | E7: 49 | F7: Stereen | H7: https://www.steren.com.mx/llantas-de-plastico.html | I7: =E7*C7 -> 490
A8: Paquete De 100 Fotorresistencias Ldr 5 Mm Sensor De Luz 5516 Tecneu | B8: PZA | C8: 2 | E8: 134.09 | F8: Mercado Libre | H8: https://www.mercadolibre.com.mx/paquete-de-100-fotorresistencias-ldr-5-mm-sensor-de-luz-5516-tecneu/p/MLM50938693#polycard_client=search-desktop&be_origin=backend&overlay_label=not_apply&search_layout=grid&position=4&type=product&tracking_id=38756c6a-d6cd-48be-9f4a-f5048395610f&wid=MLM3730253870&sid=search | I8: =E8*C8 -> 268.18
A9: Micro Switch Push 4 terminales 12V | B9: KIT | C9: 3 | E9: 96 | F9: Mercado Libre | H9: https://www.mercadolibre.com.mx/kit-de-180-push-button-boton-4-pines-10-tamanos-switch-caja/up/MLMU710903762?pdp_filters=item_id:MLM2085754367#polycard_client=recommendations_vip-pads-up&reco_backend=recomm_platform_base_pads_ron_MERGE_marketplace&reco_model=recos_backend_only&reco_client=vip-pads-up&reco_item_pos=2&reco_backend_type=low_level&reco_id=0803ace9-cd71-446f-9dcf-202bcf15fa48&wid=MLM2085754367&sid=recos&is_advertising=true&ad_domain=VIPDESKTOP_UP&ad_position=3&ad_click_id=ZTQyNTNmZjItYjJlNy00MGI4LWE1OGQtYzkwYjU3OWU3YTFj | I9: =E9*C9 -> 288
A10: Pila Alcalina de 9 V Alta capacidad | B10: PZA | C10: 20 | E10: 59 | F10: Stereen | H10: https://www.steren.com.mx/pila-alcalina-ultra-9v-cuadrada-de-larga-duracion.html | I10: =E10*C10 -> 1180
A11: Multimetro Digital Basico | B11: PZA | C11: 10 | E11: 99.01 | F11: Stereen | H11: https://www.steren.com.mx/multimetro-compacto-economico.html | I11: =E11*C11 -> 990.1
A12: Motorreductor Recto 48:1 Motor | B12: PZA | C12: 5 | E12: 258.81 | F12: Mercado Libre | H12: https://www.mercadolibre.com.mx/20-pzas-motorreductor-recto-481-motor-2-ejes-arduino/up/MLMU2982455006#polycard_client=search-desktop&be_origin=backend&overlay_label=not_apply&search_layout=grid&position=5&type=product&tracking_id=29515c33-b03d-4c80-915e-0d2167729923&wid=MLM3541658230&sid=search | I12: =E12*C12 -> 1294.05
A13: Servomotor Practinet SG90 Micro Servo 1.8kgcm Arduino Raspberry | B13: PZA | C13: 30 | E13: 89 | F13: Mercado Libre | H13: https://www.mercadolibre.com.mx/servomotor-practinet-sg90-micro-servo-18kgcm-arduino-raspberry/p/MLM46839997?pdp_filters=item_id:MLM5841824004#is_advertising=true&searchVariation=MLM46839997&backend_model=search-backend&be_origin=backend&position=19&search_layout=grid&type=pad&tracking_id=1b07fee3-cc47-473e-8060-7d9967da6741&ad_domain=VQCATCORE_LST&ad_position=19&ad_click_id=ZTI1ZWUwNzItNzg3My00ZWMwLWJkYjAtYjMyYTU4NzEwOTUw | I13: =E13*C13 -> 2670
A14: Sensor Ultrasonico Hc-sr04 Arduino | B14: PZA | C14: 15 | E14: 69 | F14: Mercado Libre | H14: https://www.mercadolibre.com.mx/sensor-ultrasonico-hc-sr04-arduino/p/MLM46959601 | I14: =E14*C14 -> 1035
... A20: Adeske Kit de Limpieza para PC Soplador de Aire Inalámbrico 300000 RPM 4 Velocidades 4 Boquillas 10 Cepillos Batería 8000mAh Recargable Luz LED Pantalla LED | B20: PZA | C20: 2 | E20: 363.09 | F20: Mercado Libre | H20: https://www.mercadolibre.com.mx/adeske-kit-de-limpieza-para-pc-soplador-de-aire-inalambrico-300000-rpm-4-velocidades-4-boquillas-10-cepillos-bateria-8000mah-recargable-luz-led-pantalla-led/p/MLM75893733?pdp_filters=item_id:MLM5847120474#is_advertising=true&searchVariation=MLM75893733&backend_model=search-backend&be_origin=backend&position=4&search_layout=grid&type=pad&tracking_id=1f9f0d86-6c56-4673-b889-9d8669b82c4a&ad_domain=VQCATCORE_LST&ad_position=4&ad_click_id=MjkxYWIzZmQtOWVlZC00NzgwLWE5OTYtMTVmZDNhYWQ1Yjkx | I20: =E20*C20 -> 726.18

Sheet REQUI P2941
D1: INSTITUTO POBLANO DE LOS PUEBLOS INDÍGENAS | H1: FORMATO DE REQUISICIÓN
D2: DIRECCIÓN DE ADMINISTRACIÓN Y FINANZAS | H2: No.
D3: DEPARTAMENTO DE RECURSOS MATERIALES Y SERVICIOS GENERALES
H4: FECHA: | J4: =TODAY() -> 46307
A6: DIRECCIÓN O UNIDAD SOLICITANTE: | E6: SUBDIRECCIÓN DE DESARROLLO DE TECNOLOGÍAS DE LA INFORMACIÓN
A7: RESPONSABLE DE LA DIRECCIÓN: | E7: MIGUEL TRINIDAD GÓMEZ HERNÁNDEZ
A8: PARTIDA PRESUPUESTAL-OBJETO DE GASTO: | E8: 2141 | G8: UR: | I8: 169
A9: PRESUPUESTO: | E9: 40436.26 | G9: COMPONENTE: | I9: C3 | M9: TOTAL | N9: + IVA
A10: FECHA PARA CUANDO SE REQUIERE: | E10: 46328 | G10: ACTIVIDAD: | I10: A9 | M10: =SUM(N13:N30) -> 33630.94 | N10: =M10*1.16 -> 39011.89
A12: No. | B12: DESCRIPCIÓN DEL BIEN Y/O SERVICIO | H12: UNIDAD DE MEDIDA | J12: CANTIDAD SOLICITADA | M12: PRECIOS | N12: SUB TOTAL | O12: LINKS
A13: 1 | B13: ='P2941'!A3 -> Pasta Térmica Arctic Cooling Mx-4 De 4g 8 Años Distribuidor | H13: ='P2941'!B3 -> PZA | J13: ='P2941'!C3 -> 10 | M13: ='P2941'!E3 -> 289 | N13: =J13*M13 -> 2890 | O13: ='P2941'!H3 -> https://www.mercadolibre.com.mx/pasta-termica-arctic-cooling-mx4-de-4g-8-anos-distribuidor/up/MLMU723390533?pdp_filters=item_id:MLM834663191#polycard_client=cart_list&wid=MLM834663191&sid=cart
A14: =+A13+1 -> 2 | B14: ='P2941'!A4 -> Ssd Adata Su630 480gb 2.5 Sata Iii 520/450 Mb/s Asu630ss-480 | H14: ='P2941'!B4 -> PZA | J14: ='P2941'!C4 -> 5 | M14: ='P2941'!E4 -> 1440 | N14: =J14*M14 -> 7200 | O14: ='P2941'!H4 -> https://www.mercadolibre.com.mx/ssd-adata-su630-480gb-25-sata-iii-520450-mbs-asu630ss-480/p/MLM27038197#polycard_client=search-desktop&be_origin=backend&overlay_label=not_apply&search_layout=grid&position=13&type=product&tracking_id=41fc4ced-0d99-4260-800f-c5f297adc99e&wid=MLM5139264412&sid=search
A15: =+A14+1 -> 3 | B15: ='P2941'!A5 -> Memoria RAM Rasalas DDR3 2x8GB 16GB PC3-10600S SODIMM para Laptops GAMER DDR3-1333MHz | H15: ='P2941'!B5 -> PZA | J15: ='P2941'!C5 -> 5 | M15: ='P2941'!E5 -> 818.88 | N15: =J15*M15 -> 4094.4 | O15: ='P2941'!H5 -> https://www.mercadolibre.com.mx/memoria-ram-rasalas-ddr3-2x8gb-16gb-pc3-10600s-sodimm-para-laptops-gamer-ddr3-1333mhz/p/MLM43884017#polycard_client=search-desktop&be_origin=backend&overlay_label=not_apply&search_layout=grid&position=67&type=product&tracking_id=f890b0e0-ed7a-45e5-b9f9-262dc6828778&wid=MLM2473187719&sid=search
A16: =+A15+1 -> 4 | B16: ='P2941'!A6 -> Memoria RAM Gamer Rasalas 8GB DDR3 1600MHz DIMM Azul para PC de Escritorio | H16: ='P2941'!B6 -> PZA | J16: ='P2941'!C6 -> 5 | M16: ='P2941'!E6 -> 448.59 | N16: =J16*M16 -> 2242.95 | O16: ='P2941'!H6 -> https://www.mercadolibre.com.mx/memoria-ram-gamer-rasalas-8gb-ddr3-1600mhz-dimm-azul-para-pc-de-escritorio/p/MLM43805151?pdp_filters=item_id:MLM3717436146#polycard_client=recommendations_pdp-pads-up&reco_backend=recomm_platform_base_pads_ron_MERGE&reco_model=search_recos_backend_merge&reco_client=pdp-pads-up&reco_item_pos=1&reco_backend_type=low_level&reco_id=9c077bb5-a13e-4524-99f7-7fdd76f83500&wid=MLM3717436146&sid=recos&is_advertising=true&ad_domain=PDPDESKTOP_UP&ad_position=2&ad_click_id=Y2FiZjQ2N2ItNmZhNy00YjllLTk3MDEtNzFkYTc5MzFkOGUw&gid=1&pid=1
A17: =+A16+1 -> 5 | B17: ='P2941'!A7 -> Memoria RAM DDR3 8GB (2x4GB) 1333MHz UDIMM Escritorio Rasalas Gamer | H17: ='P2941'!B7 -> PZA | J17: ='P2941'!C7 -> 5 | M17: ='P2941'!E7 -> 381.18 | N17: =J17*M17 -> 1905.9 | O17: ='P2941'!H7 -> https://www.mercadolibre.com.mx/memoria-ram-ddr3-8gb-2x4gb-1333mhz-udimm-escritorio-rasalas-gamer/p/MLM50768576?pdp_filters=shipping:fulfillment#intervention_type=full&position=1&search_layout=grid&type=cart_intervention&tracking_id=4cb1fe74-0ce4-447f-9c8d-cb6047655249
A18: =+A17+1 -> 6 | B18: ='P2941'!A8 -> Cable De Corriente Alimentación 2m Color Negro | H18: ='P2941'!B8 -> PZA | J18: ='P2941'!C8 -> 6 | M18: ='P2941'!E8 -> 106 | N18: =J18*M18 -> 636 | O18: ='P2941'!H8 -> https://www.mercadolibre.com.mx/cable-de-corriente-alimentacion-2m-cobre-puro-color-negro/up/MLMU3299979116?pdp_filters=shipping:fulfillment#intervention_type=full&position=3&search_layout=grid&type=cart_intervention&tracking_id=2c67f58b-543a-4fe1-a13c-b50bb0a5223d
A19: =+A18+1 -> 7 | B19: ='P2941'!A9 -> Cable Convertidor Displayport A Vga,hd 1,8 M 1080p 60hz Aomu | H19: ='P2941'!B9 -> PZA | J19: ='P2941'!C9 -> 6 | M19: ='P2941'!E9 -> 98 | N19: =J19*M19 -> 588 | O19: ='P2941'!H9 -> https://www.mercadolibre.com.mx/cable-convertidor-displayport-a-vgahd-18-m-1080p-60hz-aomu/up/MLMU4967697705#polycard_client=search-desktop&be_origin=backend&overlay_label=not_apply&search_layout=grid&position=17&type=product&tracking_id=a32d498f-1547-42e5-a3a6-5bffc6e11dbd&wid=MLM6112426306&sid=search
A20: =+A19+1 -> 8 | B20: ='P2941'!A10 -> JeeYee Cable Displayport A Hdmi Dp Blindado Hdmi 1.8m Negro, Soporta Resolución Hd, Dp Macho A Hdmi Macho, Nota No Soporta Hdmi A Dp | H20: ='P2941'!B10 -> PZA | J20: ='P2941'!C10 -> 6 | M20: ='P2941'!E10 -> 87.36 | N20: =J20*M20 -> 524.16 | O20: ='P2941'!H10 -> https://www.mercadolibre.com.mx/jeeyee-cable-displayport-a-hdmi-dp-blindado-hdmi-18m-negro-soporta-resolucion-hd-dp-macho-a-hdmi-macho-nota-no-soporta-hdmi-a-dp/p/MLM36980376?pdp_filters=item_id:MLM5860275200#is_advertising=true&searchVariation=MLM36980376&backend_model=search-backend&be_origin=backend&position=1&search_layout=grid&type=pad&tracking_id=6ce81a08-c110-43c3-8c96-f44853057bc4&ad_domain=VQCATCORE_LST&ad_position=1&ad_click_id=NDlkMTJhYTUtZjk1MC00MGE2LWFhMWUtMGQ5NDVlNmI3ODRj
A21: =+A20+1 -> 9 | B21: ='P2941'!A11 -> Cable Ugreen DisplayPort 1.4 de 3 Metros para 8K@60Hz con Blindaje y FreeSync | H21: ='P2941'!B11 -> PZA | J21: ='P2941'!C11 -> 6 | M21: ='P2941'!E11 -> 318 | N21: =J21*M21 -> 1908 | O21: ='P2941'!H11 -> https://www.mercadolibre.com.mx/cable-ugreen-displayport-14-de-3-metros-para-8k60hz-con-blindaje-y-freesync/p/MLM44469737#polycard_client=search-desktop&be_origin=backend&overlay_label=not_apply&search_layout=grid&position=1&type=product&tracking_id=293cae60-bab9-48c0-a991-24fb7d5cdbf0&wid=MLM3678884036&sid=search
A22: =+A21+1 -> 10 | B22: ='P2941'!A12 -> 25 Pilas Cr2032 De Litio 3v Cr-2032 3 Volts Para Bios Pc | H22: ='P2941'!B12 -> KIT | J22: ='P2941'!C12 -> 2 | M22: ='P2941'!E12 -> 259 | N22: =J22*M22 -> 518 | O22: ='P2941'!H12 -> https://www.mercadolibre.com.mx/25-pilas-cr2032-de-litio-3v-cr-2032-3-volts-para-bios-pc/p/MLM2082466341?pdp_filters=item_id%3AMLM1693612143&sid=bookmarks#polycard_client=bookmark&wid=MLM1693612143&sid=bookmarks
A23: =+A22+1 -> 11 | B23: ='P2941'!A13 -> Hub 6 En 1 Ugreen Usb-c A 1 Hdmi, 3 Usb A, 2 Sd/tf 5gbps Gris | H23: ='P2941'!B13 -> PZA | J23: ='P2941'!C13 -> 4 | M23: ='P2941'!E13 -> 554 | N23: =J23*M23 -> 2216 | O23: ='P2941'!H13 -> https://www.mercadolibre.com.mx/hub-6-en-1-ugreen-usb-c-a-1-hdmi-3-usb-a-2-sdtf-5gbps-gris/p/MLM34491153?pdp_filters=item_id%3AMLM2987561638&sid=bookmarks#polycard_client=bookmark&wid=MLM2987561638&sid=bookmarks&gid=1&pid=1
A24: =+A23+1 -> 12 | B24: ='P2941'!A14 -> Cámara web Logitech Brio 4K 90FPS. | H24: ='P2941'!B14 -> PZA | J24: ='P2941'!C14 -> 2 | M24: ='P2941'!E14 -> 2521.08 | N24: =J24*M24 -> 5042.16 | O24: ='P2941'!H14 -> https://www.mercadolibre.com.mx/camara-web-logitech-brio-4k-90fps/p/MLM18932094#reviews
A25: =+A24+1 -> 13 | B25: ='P2941'!A15 -> Estación De Desoldadura Yihua Cautín Para Soldar 2 En 1 Lupa | H25: ='P2941'!B15 -> PZA | J25: ='P2941'!C15 -> 1 | M25: ='P2941'!E15 -> 1473.15 | N25: =J25*M25 -> 1473.15 | O25: ='P2941'!H15 -> https://articulo.mercadolibre.com.mx/MLM-3421178670-estacion-de-desoldadura-yihua-cautin-para-soldar-2-en-1-lupa-_JM?sid=bookmarks#polycard_client=wishlist&sid=bookmarks
... A30: =+A29+1 -> 18 | B30: ='P2941'!A20 -> Cinta De Contacto Doble, 10 M, Negra Volteck 46326 Color Negro Liso | H30: ='P2941'!B20 -> PZA | J30: ='P2941'!C20 -> 5 | M30: ='P2941'!E20 -> 195 | N30: =J30*M30 -> 975 | O30: ='P2941'!H20 -> https://www.mercadolibre.com.mx/cinta-de-contacto-doble-10-m-negra-volteck-46326-color-negro-liso/p/MLM24763305#polycard_client=search-desktop&float_highlight=last_units&be_origin=backend&overlay_label=not_apply&search_layout=grid&position=1&type=product&tracking_id=6e5c1d39-f975-475c-b33f-88b5cf789923&wid=MLM1927551853&sid=search
A32: JUSTIFICACIÓN: | D32: Materiales, útiles y equipos menores de tecnologías de la información y comunicaciones, para la implementación de cursos en Introducción a la Electrónica con Arduino, Sensores y Actuadores en Módulos de Apropiación Digital con Identidad. | H32: AUTORIZACION DIRECCION GENERAL
A35: ELABORÓ | C35: NOMBRE: | D35: MIGUEL TRINIDAD GÓMEZ HERNÁNDEZ
A36: Y SOLICITÓ | C36: AREA: | D36: SUBDIRECCIÓN DE DESARROLLO DE TECNOLOGÍAS DE LA INFORMACIÓN
A37: Vo. Bo. | C37: NOMBRE: | D37: YAIR OROPEZA RAMOS
C38: AREA: | D38: DEPARTAMENTO DE RECURSOS MATERIALES Y SERVICIOS GENERALES
A39: AUTORIZÓ | C39: NOMBRE: | D39: APOLINARIA MARTÍNEZ ARROYO
C40: AREA: | D40: DIRECTORA GENERAL DEL INSTITUTO POBLANO DE LOS PUEBLOS INDÍGENAS

Sheet P2941
E1: =SUM(Tabla2[Total]) -> 33630.94 | F1: =E1*1.16 -> 39011.89
A2: Descripción | B2: UM | C2: Cantidad | D2: Diseño | E2: Precio Público | F2: Proveedor Referencia | G2: Imagen Referencia | H2: Liga de referencia | I2: Total
A3: Pasta Térmica Arctic Cooling Mx-4 De 4g 8 Años Distribuidor | B3: PZA | C3: 10 | E3: 289 | F3: Mercado Libre | H3: https://www.mercadolibre.com.mx/pasta-termica-arctic-cooling-mx4-de-4g-8-anos-distribuidor/up/MLMU723390533?pdp_filters=item_id:MLM834663191#polycard_client=cart_list&wid=MLM834663191&sid=cart | I3: =E3*C3 -> 2890
A4: Ssd Adata Su630 480gb 2.5 Sata Iii 520/450 Mb/s Asu630ss-480 | B4: PZA | C4: 5 | E4: 1440 | F4: Mercado Libre | H4: https://www.mercadolibre.com.mx/ssd-adata-su630-480gb-25-sata-iii-520450-mbs-asu630ss-480/p/MLM27038197#polycard_client=search-desktop&be_origin=backend&overlay_label=not_apply&search_layout=grid&position=13&type=product&tracking_id=41fc4ced-0d99-4260-800f-c5f297adc99e&wid=MLM5139264412&sid=search | I4: =E4*C4 -> 7200
A5: Memoria RAM Rasalas DDR3 2x8GB 16GB PC3-10600S SODIMM para Laptops GAMER DDR3-1333MHz | B5: PZA | C5: 5 | E5: 818.88 | F5: Mercado Libre | H5: https://www.mercadolibre.com.mx/memoria-ram-rasalas-ddr3-2x8gb-16gb-pc3-10600s-sodimm-para-laptops-gamer-ddr3-1333mhz/p/MLM43884017#polycard_client=search-desktop&be_origin=backend&overlay_label=not_apply&search_layout=grid&position=67&type=product&tracking_id=f890b0e0-ed7a-45e5-b9f9-262dc6828778&wid=MLM2473187719&sid=search | I5: =E5*C5 -> 4094.4
A6: Memoria RAM Gamer Rasalas 8GB DDR3 1600MHz DIMM Azul para PC de Escritorio | B6: PZA | C6: 5 | E6: 448.59 | F6: Mercado Libre | H6: https://www.mercadolibre.com.mx/memoria-ram-gamer-rasalas-8gb-ddr3-1600mhz-dimm-azul-para-pc-de-escritorio/p/MLM43805151?pdp_filters=item_id:MLM3717436146#polycard_client=recommendations_pdp-pads-up&reco_backend=recomm_platform_base_pads_ron_MERGE&reco_model=search_recos_backend_merge&reco_client=pdp-pads-up&reco_item_pos=1&reco_backend_type=low_level&reco_id=9c077bb5-a13e-4524-99f7-7fdd76f83500&wid=MLM3717436146&sid=recos&is_advertising=true&ad_domain=PDPDESKTOP_UP&ad_position=2&ad_click_id=Y2FiZjQ2N2ItNmZhNy00YjllLTk3MDEtNzFkYTc5MzFkOGUw&gid=1&pid=1 | I6: =E6*C6 -> 2242.95
A7: Memoria RAM DDR3 8GB (2x4GB) 1333MHz UDIMM Escritorio Rasalas Gamer | B7: PZA | C7: 5 | E7: 381.18 | F7: Mercado Libre | H7: https://www.mercadolibre.com.mx/memoria-ram-ddr3-8gb-2x4gb-1333mhz-udimm-escritorio-rasalas-gamer/p/MLM50768576?pdp_filters=shipping:fulfillment#intervention_type=full&position=1&search_layout=grid&type=cart_intervention&tracking_id=4cb1fe74-0ce4-447f-9c8d-cb6047655249 | I7: =E7*C7 -> 1905.9
A8: Cable De Corriente Alimentación 2m Color Negro | B8: PZA | C8: 6 | E8: 106 | F8: Mercado Libre | H8: https://www.mercadolibre.com.mx/cable-de-corriente-alimentacion-2m-cobre-puro-color-negro/up/MLMU3299979116?pdp_filters=shipping:fulfillment#intervention_type=full&position=3&search_layout=grid&type=cart_intervention&tracking_id=2c67f58b-543a-4fe1-a13c-b50bb0a5223d | I8: =E8*C8 -> 636
A9: Cable Convertidor Displayport A Vga,hd 1,8 M 1080p 60hz Aomu | B9: PZA | C9: 6 | E9: 98 | F9: Mercado Libre | H9: https://www.mercadolibre.com.mx/cable-convertidor-displayport-a-vgahd-18-m-1080p-60hz-aomu/up/MLMU4967697705#polycard_client=search-desktop&be_origin=backend&overlay_label=not_apply&search_layout=grid&position=17&type=product&tracking_id=a32d498f-1547-42e5-a3a6-5bffc6e11dbd&wid=MLM6112426306&sid=search | I9: =E9*C9 -> 588
A10: JeeYee Cable Displayport A Hdmi Dp Blindado Hdmi 1.8m Negro, Soporta Resolución Hd, Dp Macho A Hdmi Macho, Nota No Soporta Hdmi A Dp | B10: PZA | C10: 6 | E10: 87.36 | F10: Mercado Libre | H10: https://www.mercadolibre.com.mx/jeeyee-cable-displayport-a-hdmi-dp-blindado-hdmi-18m-negro-soporta-resolucion-hd-dp-macho-a-hdmi-macho-nota-no-soporta-hdmi-a-dp/p/MLM36980376?pdp_filters=item_id:MLM5860275200#is_advertising=true&searchVariation=MLM36980376&backend_model=search-backend&be_origin=backend&position=1&search_layout=grid&type=pad&tracking_id=6ce81a08-c110-43c3-8c96-f44853057bc4&ad_domain=VQCATCORE_LST&ad_position=1&ad_click_id=NDlkMTJhYTUtZjk1MC00MGE2LWFhMWUtMGQ5NDVlNmI3ODRj | I10: =E10*C10 -> 524.16
A11: Cable Ugreen DisplayPort 1.4 de 3 Metros para 8K@60Hz con Blindaje y FreeSync | B11: PZA | C11: 6 | E11: 318 | F11: Mercado Libre | H11: https://www.mercadolibre.com.mx/cable-ugreen-displayport-14-de-3-metros-para-8k60hz-con-blindaje-y-freesync/p/MLM44469737#polycard_client=search-desktop&be_origin=backend&overlay_label=not_apply&search_layout=grid&position=1&type=product&tracking_id=293cae60-bab9-48c0-a991-24fb7d5cdbf0&wid=MLM3678884036&sid=search | I11: =E11*C11 -> 1908
A12: 25 Pilas Cr2032 De Litio 3v Cr-2032 3 Volts Para Bios Pc | B12: KIT | C12: 2 | E12: 259 | F12: Mercado Libre | H12: https://www.mercadolibre.com.mx/25-pilas-cr2032-de-litio-3v-cr-2032-3-volts-para-bios-pc/p/MLM2082466341?pdp_filters=item_id%3AMLM1693612143&sid=bookmarks#polycard_client=bookmark&wid=MLM1693612143&sid=bookmarks | I12: =E12*C12 -> 518
A13: Hub 6 En 1 Ugreen Usb-c A 1 Hdmi, 3 Usb A, 2 Sd/tf 5gbps Gris | B13: PZA | C13: 4 | E13: 554 | F13: Mercado Libre | H13: https://www.mercadolibre.com.mx/hub-6-en-1-ugreen-usb-c-a-1-hdmi-3-usb-a-2-sdtf-5gbps-gris/p/MLM34491153?pdp_filters=item_id%3AMLM2987561638&sid=bookmarks#polycard_client=bookmark&wid=MLM2987561638&sid=bookmarks&gid=1&pid=1 | I13: =E13*C13 -> 2216
A14: Cámara web Logitech Brio 4K 90FPS. | B14: PZA | C14: 2 | E14: 2521.08 | F14: Mercado Libre | H14: https://www.mercadolibre.com.mx/camara-web-logitech-brio-4k-90fps/p/MLM18932094#reviews | I14: =E14*C14 -> 5042.16
... A20: Cinta De Contacto Doble, 10 M, Negra Volteck 46326 Color Negro Liso | B20: PZA | C20: 5 | E20: 195 | F20: Mercado Libre | H20: https://www.mercadolibre.com.mx/cinta-de-contacto-doble-10-m-negra-volteck-46326-color-negro-liso/p/MLM24763305#polycard_client=search-desktop&float_highlight=last_units&be_origin=backend&overlay_label=not_apply&search_layout=grid&position=1&type=product&tracking_id=6e5c1d39-f975-475c-b33f-88b5cf789923&wid=MLM1927551853&sid=search | I20: =E20*C20 -> 975

Sheet P2941 2024-02-12
A1: Anexo1
A2: Descripción | B2: Cantidad | C2: Diseño | D2: Precio Público | E2: Proveedor Referencia | F2: Imagen Referencia | G2: Liga de referencia | H2: Total
A3: Startech.com Splitter Multiplicador Divisor Mini DisplayPort de 3 Puertos Triple Head | B3: 1 | D3: 809 | E3: CYBERPUERTA | G3: https://www.cyberpuerta.mx/Computo-Hardware/Adaptadores/Adaptadores-Video/Divisores-de-Video/Manhattan-Divisor-de-Video-Mini-DisplayPort-Macho-4x-DisplayPort-Hembra-Negro.html?gad_source=1&gclid=Cj0KCQiAoKeuBhCoARIsAB4Wxtdr8P_rGLtXoxmmI0OaW0W7-at1ex1R_pzCZwCN7mO4L0_AMZ6eB2YaAohtEALw_wcB | H3: =D3*B3 -> 809
A4: SSD 2.5 480GB Seagate SATA III BarraCuda 6Gb/s 7MM | B4: 2 | D4: 580 | E4: BIG COM | G4: https://bigcom.mx/producto/ssd-2-5-480gb-seagate-sata-iii-barracuda-6gb-s-7mm/?srsltid=AfmBOorVcuK0ZqL4kvA6iB4T5eCIA1YLhPVG5jRwEROQKUOogUrTqEkuuFw | H4: =D4*B4 -> 1160
A5: Mezcladora Interfaz de Audio MAONO Maonocaster Lite Estudio de Grabación Portátil TODO EN UNO con Micrófono de 3.5mm para Podcast, Streaming, Guitarra, Grabación y Gamer (AM200-S1) | B5: 2 | D5: 1798 | E5: Amazon | G5: https://www.amazon.com.mx/Mezcladora-MAONO-Maonocaster-Grabaci%C3%B3n-AU-AM200-S1/dp/B09MT8KH4V/ref=asc_df_B09MT8KH4V/?tag=gledskshopmx-20&linkCode=df0&hvadid=563294944682&hvpos=&hvnetw=g&hvrand=3757154746713579155&hvpone=&hvptwo=&hvqmt=&hvdev=c&hvdvcmdl=&hvlocint=&hvlocphy=9073959&hvtargid=pla-1637132724653&mcid=1f57b376a6f83dfc8e966454dd43976f&th=1 | H5: =D5*B5 -> 3596
A6: Sistema Profesional De 2 Micrófonos Inalámbricos |wr-810 Uhf para grabación de transmisiones en vivo de redes sociales | B6: 2 | D6: 2490 | E6: Steren | G6: https://www.steren.com.mx/sistema-profesional-de-2-microfonos-inalambricos-uhf-con-bateria-recargable.html?utm_term=&utm_campaign=PM+-+General+-+MHA+Test&utm_source=adwords&utm_medium=ppc&hsa_acc=3543146321&hsa_cam=20510601344&hsa_grp=&hsa_ad=&hsa_src=x&hsa_tgt=&hsa_kw=&hsa_mt=&hsa_net=adwords&hsa_ver=3&gad_source=1&gclid=Cj0KCQiAoKeuBhCoARIsAB4Wxtd0irgsOhtALHUrdzUZmXII4uFdMG_Ve3TJmWKr7L-ekvrMaPR0OcIaAnwKEALw_wcB | H6: =D6*B6 -> 4980
A7: Mezclador de audio digital, placa de sonido, control de volumen independiente MP3, entrada USB para grabación de video conferencias | B7: 2 | D7: 1798 | E7: Amazon | G7: https://www.amazon.com.mx/mezcladora-profesional-mezclador-independiente-grabaci%C3%B3n/dp/B0C1XZJ6S1/ref=asc_df_B0C1XZJ6S1/?tag=gledskshopmx-20&linkCode=df0&hvadid=673386236624&hvpos=&hvnetw=g&hvrand=3757154746713579155&hvpone=&hvptwo=&hvqmt=&hvdev=c&hvdvcmdl=&hvlocint=&hvlocphy=9073959&hvtargid=pla-2311806740397&psc=1&mcid=0161d19092643778936e9d56bb3c00ca | H7: =D7*B7 -> 3596
H8: =SUM(H3:H7) -> 14141
G9: Total + Iva: | H9: =H8*1.16 -> 16403.56

Sheet P2141 2024-06-28
A1: =CONCATENATE( CONVERTIR_A_NUMERO(H2,"PESO", "PESOS",0,"M.N.") ) -> #NAME? | G1: Sub Total: | H1: =SUM(H4:H13) -> 25797.96
G2: Total: | H2: =H1*1.16 -> 29925.634
A3: Descripción | B3: Cantidad | C3: Diseño | D3: Precio Público | E3: Proveedor Referencia | F3: Imagen Referencia | G3: Liga de referencia | H3: Total
A4: 2 Pack Gaming Aluminum Mouse Pad (Silver & Black) Compatible with Magic Mouse, DaKuan Smooth Magic Ultra Thin Double Side Mouse Mat for Fast and Accurate Control (9 inch X 7.1 inch) | B4: 1 | D4: 379.71 | E4: Amazon | G4: https://www.amazon.com.mx/Aluminum-Compatible-DaKuan-Accurate-Control%C3%82/dp/B07KR232BS/ref=asc_df_B07KR232BS/?hvadid=522170751353&hvdev=c&hvdvcmdl=undefined&hvlocint=undefined&hvlocphy=9073959&hvnetw=g&hvpone=undefined&hvpos=undefined&hvptwo=undefined&hvqmt=undefined&hvrand=4331110660744140969&hvtargid=pla-637927448130&linkCode=df0&mcid=bd22954ea11637ac9135829810109b49&tag=gledskshopmx-20&th=1 | H4: =D4*B4 -> 379.71
A5: KAQIAO - Funda de TV para exteriores, protector de visualización de TV de 40 a 42 pulgadas, lona 600D, resistente al agua, material resistente a la decoloración, para la serie SWITCH en lona impermeable para LCD, LED, negro (40-42 pulgadas) | B5: 3 | D5: 594.38 | E5: Amazon | G5: https://www.amazon.com.mx/KAQIAO-exteriores-visualizaci%C3%B3n-decoloraci%C3%B3n-impermeable/dp/B0CF649311/ref=sr_1_2?__mk_es_MX=%C3%85M%C3%85%C5%BD%C3%95%C3%91&crid=OU3YN331L8YT&dib=eyJ2IjoiMSJ9.cmDCTMH0gKU4ZAZoFfuMFWD8uGGhGK8tCcdxLgIxRvt1glAMLFI6BDdLUYqbW3qs7-QHM1Napj82nbZMF8ZCx7mu1akKyW5uFqvtYdiqFIfMN7aiNWmlGNHnX1u2G1tR0N-r5MkhpUjARuLsC6S4uz2kw9cEcGqViBeIkaWngu8Q1kqtDpP7tG50TxDIpFPg0uu2s42brM0wC7HzeaeQ5vRI_Ws2xW2edM8qB_weGCfHYCZvSfB064XZNDxqlDzAPmt2JXwLyCcYrCsfmMLGDwp9vNFmUWM7kS2ZSV7qRNk.MsQHSJg9GTM1dFTLfQAnmXmi5zTh-2lU4zpvnK1H0uc&dib_tag=se&keywords=fundas%2Bde%2Btransporte%2Bde%2Bpantalla%2B40%2BPULGADAS&qid=1719333447&s=electronics&sprefix=fundas%2Bde%2Btransporte%2Bde%2Bpantalla%2B40%2Bpulgada%2Celectronics%2C99&sr=1-2&ufe=app_do%3Aamzn1.fos.242f5c11-6cfd-40d6-91f6-be3d1974080c&th=1 | H5: =D5*B5 -> 1783.14
A6: Microfono Podcast Condensador De 3.5mm Maono A03 Pc Celular | B6: 3 | D6: 783.22 | E6: Mercado Libre | G6: https://articulo.mercadolibre.com.mx/MLM-814194293-microfono-podcast-condensador-de-35mm-maono-a03-pc-celular-_JM | H6: =D6*B6 -> 2349.66
A7: MAONO - Mezcladora Interfaz de Audio caster Lite Estudio de Grabación Portátil TODO EN UNO con Micrófono de 3.5mm para Podcast, Streaming, Guitarra, Grabación y Gamer (AM200-S1) | B7: 1 | D7: 2860.65 | E7: Amazon | G7: https://www.amazon.com.mx/Mezcladora-MAONO-Maonocaster-Grabaci%C3%B3n-AU-AM200-S1/dp/B09MT8KH4V/ref=asc_df_B09MT8KH4V/?tag=gledskshopmx-20&linkCode=df0&hvadid=563294944682&hvpos=&hvnetw=g&hvrand=5315120693458104469&hvpone=&hvptwo=&hvqmt=&hvdev=c&hvdvcmdl=&hvlocint=&hvlocphy=9073959&hvtargid=pla-1637132724653&psc=1&mcid=1f57b376a6f83dfc8e966454dd43976f | H7: =D7*B7 -> 2860.65
A8: Dorkis Escudo de Aislamiento de 5 Paneles, Escudo de Aislamiento para Micrófono, Aislamiento de Cabina Vocal Portátil, Cabina de Grabación, Escudo de Aislamiento de Micrófono para Plegable | B8: 3 | D8: 621 | E8: Amazon | G8: https://www.amazon.com.mx/Dorkis-Aislamiento-Micr%C3%B3fono-Port%C3%A1til-Grabaci%C3%B3n/dp/B0C3BX57FX/ref=sr_1_1?__mk_es_MX=%C3%85M%C3%85%C5%BD%C3%95%C3%91&crid=WD9ZB34VRIQN&dib=eyJ2IjoiMSJ9.lDmlqA3Z1l67WFhfTa30vx3DCnvsOW_0pRl5AVnS79b4icV6JamgMSEUIRH_205nrM4DIMsXBHJzW8Z8y0y9r2V3sWxL4TWqghb_rKaaGFiSV-hDOY5nfZAXUWbgAy-P6x7bq2cePUGCLg5xyYpKUMOyU5VWXftlAW6HEd91uBzotsUi9zpblYtdIIGCi8dU_NrotFVlTEl2IPe-fMYD-o2TfJi3Zq2WR3t7Tuj1xRK4VqrhxWoLJSaP_glm0VyHp8e_nkV6rqLjPFhQc94HsAVrX6HF6xaiZ4W5PxwahXk.QFiyeTXaadlIVmPcrx9SU4YlINsynzD6wyKwMh9KyXU&dib_tag=se&keywords=panel+de+cancelaci%C3%B3n+de+ruido+port%C3%A1til+para+microfono&qid=1719337826&s=musical-instruments&sprefix=panel+de+cancelaci%C3%B3n+de+ruido+portatil+para+microfno%2Cmi%2C101&sr=1-1&ufe=app_do%3Aamzn1.fos.242f5c11-6cfd-40d6-91f6-be3d1974080c | H8: =D8*B8 -> 1863
A9: Caja de Luz para Fotografía(40x40cm,CRI＞95),con 140 LED Brillo Ajustable de 1-100°,Luz blanca,Cálida y Neutra,Fondo para Fotografía de 6 Colores Desmontables,Conexión USB,Adecuado para Objetos Pequeño | B9: 3 | D9: 928.8 | E9: Amazon | G9: https://www.amazon.com.mx/Fotograf%C3%ADa-Ajustable-Desmontables-Conexi%C3%B3n-Adecuado/dp/B0D4DPFGMT/ref=sr_1_10?__mk_es_MX=%C3%85M%C3%85%C5%BD%C3%95%C3%91&crid=F2K9L2PPUHUH&dib=eyJ2IjoiMSJ9.sKhOBOKYNeTIBaoXkFigtlate_171e6B7w2MkqbRS4gAoOMqz3_cm5wU4y7P0wPnEhFHbEYPRs569m8fx4sTGLlgXomsh2AKpLGVC6-4Ghmn6i-wMtdH1-A9OqrZ-fl2MtjFFr8Hcs3PQcmkJcdkahoHgR5_Q6ScpnJroSzpdH_IpNhAzhV8opsokPAfowj1beGU_RlcJPiFeTq5DLBkfe3-URXOQnRdpFp7p3X2CE55UOraq8N903sRqz-pjcpDeK8mRDsC-GKRHrEHoDiV63wOzAmsZbyz2cWkq21AmNQ.6a22msXCvR-2NVRe7ngqhQhACCePIIvDCvnpG5fA7h4&dib_tag=se&keywords=caja+de+luz+portatil&qid=1719340986&s=electronics&sprefix=caja+de+luz+portatil+%2Celectronics%2C486&sr=1-10&ufe=app_do%3Aamzn1.fos.242f5c11-6cfd-40d6-91f6-be3d1974080c | H9: =D9*B9 -> 2786.4
A10: Vl140 RGB LED Luz, Iluminación para Video, 360 a Todo Color con 20 Efectos de Iluminación. Luces para Video, Recargable, Portátil. Para Videoblogging, Fotografía, Videoconferencias y Mucho Más (Negro) | B10: 3 | D10: 538.65 | E10: Amazon | G10: https://www.amazon.com.mx/Iluminaci%C3%B3n-Iluminaci%C3%B3n-Recargable-Videoblogging-Videoconferencias/dp/B0CNTF3M66/ref=sr_1_20?__mk_es_MX=%C3%85M%C3%85%C5%BD%C3%95%C3%91&crid=VQVQK4ZUUW8C&dib=eyJ2IjoiMSJ9.crBvS8U9r5BTZEtldck9mhCHVitpxVB5eoWq98Mg7Na_PlR-AHHYs00o-V_cpaLnNDLGJoupCobh-jwfy259ZdNDzLRCRSmnGHImvF9SER816B-SZQNOOQFz_LZENZM3kAWaZ8AVCMKEprQxT5pHINoRaMNWfwplNdhuQjF426JlDpAX5tDtiyB6XDGpZCJ7QS_7Q1s-3LwoA2uJNGQ7IQuuVOlZYWPCl8WKA4TZTypprMPrcCdsVqWLB-BBoRbjpIDUJ9-XoCGoXz-G3oU1SXwOzAmsZbyz2cWkq21AmNQ.r5k1ltEaIVHm8yLKm2A-Nip9LWPff4RjGSGNqPUc4dY&dib_tag=se&keywords=kit%2Bde%2Bluces%2Bestudio%2Bportatil&qid=1719341720&s=electronics&sprefix=kit%2Bde%2Buces%2Bestudio%2Bportatil%2Celectronics%2C111&sr=1-20&ufe=app_do%3Aamzn1.fos.242f5c11-6cfd-40d6-91f6-be3d1974080c&th=1 | H10: =D10*B10 -> 1615.95
A11: Camerina Kit Iluminación Fotografía, Studio Photography Softbox Kit con 50x70cm Softbox * 2 + 2M Soporte de Trípode de Metal * 2 para Transmisión en Vivo Retrato Producto Foto Video | B11: 3 | D11: 1005.75 | E11: Amazon | G11: https://www.amazon.com.mx/Camerina-Iluminaci%C3%B3n-Fotograf%C3%ADa-Photography-Transmisi%C3%B3n/dp/B0CS6R37CC/ref=sr_1_5?__mk_es_MX=%C3%85M%C3%85%C5%BD%C3%95%C3%91&crid=2TVQOZ7IJ1PWH&dib=eyJ2IjoiMSJ9._vPA5q80oLt-WF5yDETn2BYscGvTVDo9uY29LP2C33vi4062pFy0b9bVFz3BK1ZR8MaYbVjJD4IAm1hC0UhbuvChUKp4UMr73xyg4qK9nCzltPTvXrFG5uSybPnBmYF3xcj4tpif9g1zk9EEcOwq3Nko7vgWupPLpltYAlYMXPrIicjvNnEjuMBAaH5aiNRWvHbYnzQqjSO4J8AAYbVGBbwQAOXu4qFOVRFwnttTv1dZvQpG86PMGXt3x3RI7qk8muNOZBdeFS0YIU_LayO2lHuhNBW2GAawPhZwPAocHnc.Gw7MAU8bagxXUMMFHylmG0atmfi9c-q3x4InknB4gaw&dib_tag=se&keywords=kit+de+luces&qid=1719342406&s=electronics&sprefix=kit+de+luces+%2Celectronics%2C113&sr=1-5&ufe=app_do%3Aamzn1.fos.242f5c11-6cfd-40d6-91f6-be3d1974080c | H11: =D11*B11 -> 3017.25
A12: Tripie para Proyector,Trípode para Computadora Portátil,Altura Ajustable de 60-160cm con Soporte para Teléfono Piso Plegable con Bandeja de Ajuste de Inclinación para Uso en Interiores y Exteriores | B12: 2 | D12: 808.65 | E12: Amazon | G12: https://www.amazon.com.mx/para-Computadora-Inclinaci%C3%B3n-Interiores-Exteriores/dp/B0D12PL9NN/ref=sr_1_1501?__mk_es_MX=%C3%85M%C3%85%C5%BD%C3%95%C3%91&crid=3DDDS0L1SJBGR&dib=eyJ2IjoiMSJ9.Ui9F1PjmibTr3OSXAuJGMgwfJ2_gnYVBGxd3wTACc7dqWvtKFlaI2eZ3lQ4q5yE58UUUCK7rtwkh5HcYHEQHkAN_sZRf48CglR2JAk2EgKbOYYqFnjFRXaG1JY7r5vjq2xOaHtaCKzDP1mnyvo8B4ujpRBIdbGf-FUqrbamqh8D-nNgCuhG61keOLUku7aerI4m-VWPRkRhtuLB4EkEGzA.IdhVzeevZphnoBNURvyWcN5gfJOEqTfv4VI_xstIscw&dib_tag=se&keywords=tripie&qid=1719345670&s=electronics&sprefix=tripie%2Celectronics%2C108&sr=1-1501&ufe=app_do%3Aamzn1.fos.242f5c11-6cfd-40d6-91f6-be3d1974080c | H12: =D12*B12 -> 1617.3
A13: CGYI 63" Trípode para Cámara, Tripie y Monopié Aluminio Plegable, Cabezal Esférico 360° Desmontable, Bolsa Viaje, Altura Ajustable 15.7" A 63", para Sin Espejo/DSLR/Teléfono/Videocámara/Telescopios | B13: 6 | D13: 1254.15 | E13: Amazon | G13: https://www.amazon.com.mx/CGYI-Desmontable-Ajustable-Videoc%C3%A1mara-Telescopios/dp/B0CLTY5226/ref=sr_1_1875?__mk_es_MX=%C3%85M%C3%85%C5%BD%C3%95%C3%91&crid=3DDDS0L1SJBGR&dib=eyJ2IjoiMSJ9.6-JhfJ6sK7gqTd6qDzEeDX7aHmLSDA4JrrxryfzhuXk_TLvtlfmYhH3UUH2I6ZTO_qlKiSXhcP8R1NiAgKPXMyIT2xhwGkud3vJM-gKnC4brBdOhkUchrmC3rXPcf4BkRSqrnhmNcccQy3xEJ7p6qA.-oztSE8uT0YD3UgkpsyBB0eCF0Zc2zyIOBHIyfhP1nQ&dib_tag=se&keywords=tripie&qid=1719352713&s=electronics&sprefix=tripie%2Celectronics%2C108&sr=1-1875&ufe=app_do%3Aamzn1.fos.242f5c11-6cfd-40d6-91f6-be3d1974080c | H13: =D13*B13 -> 7524.9

Sheet P2141 2024-09-26
A1: =CONCATENATE( CONVERTIR_A_NUMERO(H2,"PESO", "PESOS",0,"M.N.") ) -> #NAME? | G1: Sub Total: | H1: =SUM(H4:H10) -> 17181.58
G2: Total: | H2: =H1*1.16 -> 19930.633
A3: Descripción | B3: Cantidad | C3: Diseño | D3: Precio Público | E3: Proveedor Referencia | F3: Imagen Referencia | G3: Liga de referencia | H3: Total
A4: Router TP-Link TL-WR840n | B4: 2 | D4: 936.6 | E4: Amazon | G4: https://www.amazon.com.mx/TP-Link-configuraci%C3%B3n-Rendimiento-Archer-AX12/dp/B0CCK5GWXY/ref=asc_df_B0CCK5GWXY/?tag=gledskshopmx-20&linkCode=df0&hvadid=709966298345&hvpos=&hvnetw=g&hvrand=9044006326247153861&hvpone=&hvptwo=&hvqmt=&hvdev=c&hvdvcmdl=&hvlocint=&hvlocphy=9073959&hvtargid=pla-2200381325933&psc=1&mcid=87664fea46c5397eafb311eaaf4e8637&gad_source=1 | H4: =D4*B4 -> 1873.2
A5: Switch TP-LINK Gigabit Ethernet TL-SG108E, 8 Puertos 10/100/1000Mbps, 16 Gbit/s, 8000 Entradas - No Administrable | B5: 2 | D5: 883.05 | E5: Cyberpuerta | G5: https://www.cyberpuerta.mx/Computo-Hardware/Redes/Switches/Switch-TP-LINK-Gigabit-Ethernet-TL-SG108E-8-Puertos-10-100-1000Mbps-16-Gbit-s-8000-Entradas-No-Administrable.html?gad_source=1&gclid=Cj0KCQjwjNS3BhChARIsAOxBM6rs3wLpZ38S0zHpc769Kys7rwNSO7zVma-utxa736hRGS-CU2zxO1IaAsSREALw_wcB | H5: =D5*B5 -> 1766.1
A6: Microfono Podcast Condensador De 3.5mm Maono A03 Pc Celular | B6: 1 | D6: 1136.8 | E6: Mercado Libre | G6: https://articulo.mercadolibre.com.mx/MLM-814194293-microfono-podcast-condensador-de-35mm-maono-a03-pc-celular-_JM | H6: =D6*B6 -> 1136.8
A7: Behringer Q1202USB - Mezclador de 12 canales | B7: 4 | D7: 1467.4 | E7: Amazon | G7: https://www.amazon.com.mx/Behringer-Q1202USB-12-Channel-Mixer-Black/dp/B09Z33VY99 | H7: =D7*B7 -> 5869.6
A8: Dorkis Escudo de Aislamiento de 5 Paneles, Escudo de Aislamiento para Micrófono, Aislamiento de Cabina Vocal Portátil, Cabina de Grabación, Escudo de Aislamiento de Micrófono para Plegable | B8: 2 | D8: 900.45 | E8: Amazon | G8: https://www.amazon.com.mx/Dorkis-Aislamiento-Micr%C3%B3fono-Port%C3%A1til-Grabaci%C3%B3n/dp/B0C3BX57FX/ref=sr_1_1?__mk_es_MX=%C3%85M%C3%85%C5%BD%C3%95%C3%91&crid=WD9ZB34VRIQN&dib=eyJ2IjoiMSJ9.lDmlqA3Z1l67WFhfTa30vx3DCnvsOW_0pRl5AVnS79b4icV6JamgMSEUIRH_205nrM4DIMsXBHJzW8Z8y0y9r2V3sWxL4TWqghb_rKaaGFiSV-hDOY5nfZAXUWbgAy-P6x7bq2cePUGCLg5xyYpKUMOyU5VWXftlAW6HEd91uBzotsUi9zpblYtdIIGCi8dU_NrotFVlTEl2IPe-fMYD-o2TfJi3Zq2WR3t7Tuj1xRK4VqrhxWoLJSaP_glm0VyHp8e_nkV6rqLjPFhQc94HsAVrX6HF6xaiZ4W5PxwahXk.QFiyeTXaadlIVmPcrx9SU4YlINsynzD6wyKwMh9KyXU&dib_tag=se&keywords=panel+de+cancelaci%C3%B3n+de+ruido+port%C3%A1til+para+microfono&qid=1719337826&s=musical-instruments&sprefix=panel+de+cancelaci%C3%B3n+de+ruido+portatil+para+microfno%2Cmi%2C101&sr=1-1&ufe=app_do%3Aamzn1.fos.242f5c11-6cfd-40d6-91f6-be3d1974080c | H8: =D8*B8 -> 1800.9
A9: Camerina Kit Iluminación Fotografía, Studio Photography Softbox Kit con 50x70cm Softbox * 2 + 2M Soporte de Trípode de Metal * 2 para Transmisión en Vivo Retrato Producto Foto Video | B9: 2 | D9: 1458.34 | E9: Amazon | G9: https://www.amazon.com.mx/Camerina-Iluminaci%C3%B3n-Fotograf%C3%ADa-Photography-Transmisi%C3%B3n/dp/B0CS6R37CC/ref=sr_1_5?__mk_es_MX=%C3%85M%C3%85%C5%BD%C3%95%C3%91&crid=2TVQOZ7IJ1PWH&dib=eyJ2IjoiMSJ9._vPA5q80oLt-WF5yDETn2BYscGvTVDo9uY29LP2C33vi4062pFy0b9bVFz3BK1ZR8MaYbVjJD4IAm1hC0UhbuvChUKp4UMr73xyg4qK9nCzltPTvXrFG5uSybPnBmYF3xcj4tpif9g1zk9EEcOwq3Nko7vgWupPLpltYAlYMXPrIicjvNnEjuMBAaH5aiNRWvHbYnzQqjSO4J8AAYbVGBbwQAOXu4qFOVRFwnttTv1dZvQpG86PMGXt3x3RI7qk8muNOZBdeFS0YIU_LayO2lHuhNBW2GAawPhZwPAocHnc.Gw7MAU8bagxXUMMFHylmG0atmfi9c-q3x4InknB4gaw&dib_tag=se&keywords=kit+de+luces&qid=1719342406&s=electronics&sprefix=kit+de+luces+%2Celectronics%2C113&sr=1-5&ufe=app_do%3Aamzn1.fos.242f5c11-6cfd-40d6-91f6-be3d1974080c | H9: =D9*B9 -> 2916.68
A10: CGYI 63" Trípode para Cámara, Tripie y Monopié Aluminio Plegable, Cabezal Esférico 360° Desmontable, Bolsa Viaje, Altura Ajustable 15.7" A 63", para Sin Espejo/DSLR/Teléfono/Videocámara/Telescopios | B10: 1 | D10: 1818.3 | E10: Amazon | G10: https://www.amazon.com.mx/CGYI-Desmontable-Ajustable-Videoc%C3%A1mara-Telescopios/dp/B0CLTY5226/ref=sr_1_1875?__mk_es_MX=%C3%85M%C3%85%C5%BD%C3%95%C3%91&crid=3DDDS0L1SJBGR&dib=eyJ2IjoiMSJ9.6-JhfJ6sK7gqTd6qDzEeDX7aHmLSDA4JrrxryfzhuXk_TLvtlfmYhH3UUH2I6ZTO_qlKiSXhcP8R1NiAgKPXMyIT2xhwGkud3vJM-gKnC4brBdOhkUchrmC3rXPcf4BkRSqrnhmNcccQy3xEJ7p6qA.-oztSE8uT0YD3UgkpsyBB0eCF0Zc2zyIOBHIyfhP1nQ&dib_tag=se&keywords=tripie&qid=1719352713&s=electronics&sprefix=tripie%2Celectronics%2C108&sr=1-1875&ufe=app_do%3Aamzn1.fos.242f5c11-6cfd-40d6-91f6-be3d1974080c | H10: =D10*B10 -> 1818.3

Sheet 2023-11-01
A2: Descripción | B2: Cantidad | C2: Diseño | D2: Precio Público | E2: Proveedor Referencia | F2: Imagen Referencia | G2: Liga de referencia | H2: Total
A3: Consola - Interfaz de sistema de computadora con 6 canales, USB, Bluetooth, entrada digital de computadora MP3, potencia fantasma de 48 V, transmisión estéreo de DJ y FX16 Bit DSP-(PMXU63BT) | B3: 2 | D3: 2092.13 | E3: Amazon | G3: https://www.amazon.com.mx/Pyle-Professional-Audio-Mixer-Console/dp/B072HSWWK2/ref=sr_1_1?keywords=consola+de+audio&qid=1673125256&sprefix=consola+de+audio%2Caps%2C136&sr=8-1&ufe=app_do%3Aamzn1.fos.66c34496-0d28-4d73-a0a1-97a8d87ec0b2 | H3: =D3*B3 -> 4184.26
A4: Multicontacto Koblenz SS-550-USB Supresor de Picos, color blanco | B4: 5 | D4: 271 | E4: Amazon | G4: https://www.amazon.com.mx/Koblenz-SS-550-USB-Supresor-Picos-blanco/dp/B01MYDM09N/ref=psdc_9687283011_t2_B00TP1C1UC | H4: =D4*B4 -> 1355
A5: Cable Extension Activa Usb 2.0 Macho Hembra 20 Metros 480mbp | B5: 6 | D5: 399 | E5: Mercado Libre | G5: https://articulo.mercadolibre.com.mx/MLM-677110079-cable-extension-activa-usb-20-macho-hembra-20-metros-480mbp-_JM#is_advertising=true&position=1&search_layout=stack&type=pad&tracking_id=fffbe716-2e91-45a8-8948-347072015b23&is_advertising=true&ad_domain=VQCATCORE_LST&ad_position=1&ad_click_id=Mjg5ODBkMjUtMGY2Ny00ZjQ2LWIxYzctNTYwNDU4ZTk1MmU2 | H5: =D5*B5 -> 2394
A6: AOM Logitech BRIO UHD 4K Cámara Web: (960-001105) con tecnología RightLight 3 y HDR + Kit de Paquete | B6: 6 | D6: 3920.15 | E6: Amazon | G6: https://www.amazon.com.mx/C%C3%A1mara-web-Logitech-BRIO-UHD/dp/B08H8NZ5TN/ref=sr_1_27?__mk_es_MX=%C3%85M%C3%85%C5%BD%C3%95%C3%91&crid=23XGKH1QQJRY&keywords=camara+web+logitech&qid=1673127669&s=electronics&sprefix=camara+web+logitech%2Celectronics%2C114&sr=1-27&ufe=app_do%3Aamzn1.fos.2f990652-065f-4ce4-905d-4c9d6a080141 | H6: =D6*B6 -> 23520.9
A7: Kzeux USB 2.0 - Cable de impresora A-macho a B-macho, 32 pies (10 metros) de alta velocidad para impresora/escáner/repetidor | B7: 3 | D7: 500.82 | E7: Amazon | G7: https://www.amazon.com.mx/Cable-impresora-USB-2-0-macho/dp/B0722W29S8/ref=sr_1_5?__mk_es_MX=%C3%85M%C3%85%C5%BD%C3%95%C3%91&crid=2A8SBV3YSPYM7&keywords=cable+usb+ab+10+metros&qid=1676916492&s=industrial&sprefix=cable+usb+a+b+10+metros%2Cindustrial%2C129&sr=1-5 | H7: =D7*B7 -> 1502.46
A8: NEEWER Trípode de Cámara de 77 Pulgadas con Rótula de Bola Panorámica de 360°,Columna Central de 2 Ejes,Placa QR Tipo Arca, Aluminio Compacto,Ligero,Carga Máxima de 18 lb, Bolsa de Transporte Incluida | B8: 4 | D8: 2249.15 | E8: Amazon | G8: https://www.amazon.com.mx/dp/B081Q9YVJS/ref=redir_mobile_desktop?_encoding=UTF8&aaxitk=498a8b1312101332d7f2a83c4ab3df27&content-id=amzn1.sym.37e22799-a545-418d-9496-4236fbc8955d%3Aamzn1.sym.37e22799-a545-418d-9496-4236fbc8955d&hsa_cr_id=0&pd_rd_plhdr=t&pd_rd_r=c0acf910-ab50-4411-a1b7-357222904f5c&pd_rd_w=2hD8y&pd_rd_wg=o8wo4&qid=1676917284&ref_=sbx_be_s_sparkle_mcd_asin_1_img&sr=1-2-9e67e56a-6f64-441f-a281-df67fc737124 | H8: =D8*B8 -> 8996.6
A9: NIERBO HDMI Splitter 1X4 Salida 4K 3D 4 Divisor de Monitor Hdmi para HDTV PC para PS3/PS4 para Xbox Blue-Ray y Más | B9: 2 | D9: 499.99 | E9: Amazon | G9: https://www.amazon.com.mx/NIERBO-Splitter-Divisor-Monitor-Blue-Ray/dp/B0797P6132/ref=asc_df_B0797P6132/?tag=gledskshopmx-20&linkCode=df0&hvadid=360384033502&hvpos=&hvnetw=g&hvrand=15555250883559498267&hvpone=&hvptwo=&hvqmt=&hvdev=c&hvdvcmdl=&hvlocint=&hvlocphy=9073959&hvtargid=pla-806402509435&psc=1 | H9: =D9*B9 -> 999.98
A10: PANFREY Hub USB 3.0, Convertidor 7 en 1 Velocidad Ultra Alta Hub, Divisor USB con interruptores Individuales de Encendido y luz LED, Compatible con PC, Portátil, PS4, PS5, Xbox, Ratón, Teclado | B10: 2 | D10: 269 | E10: Amazon | G10: https://www.amazon.com.mx/dp/B0BHVF9FDL/ref=sspa_dk_detail_1?psc=1&pd_rd_i=B0BHVF9FDL&pd_rd_w=Dx0Oj&content-id=amzn1.sym.f4b065a7-c255-43f0-a2c0-b69847ce06d2&pf_rd_p=f4b065a7-c255-43f0-a2c0-b69847ce06d2&pf_rd_r=7KVB9KSRVY6KHDEK564Z&pd_rd_wg=3YSbI&pd_rd_r=5c5e222f-15c2-4e48-bae0-ca721e8d0b50&s=electronics&sp_csd=d2lkZ2V0TmFtZT1zcF9kZXRhaWw&spLa=ZW5jcnlwdGVkUXVhbGlmaWVyPUFDQ05DMDBRMlQ3QTgmZW5jcnlwdGVkSWQ9QTA0MTc0OTRZN0RTSVFaUjFMNDQmZW5jcnlwdGVkQWRJZD1BMDA2Nzk5NzJQTVNYS1FBWENPWjEmd2lkZ2V0TmFtZT1zcF9kZXRhaWwmYWN0aW9uPWNsaWNrUmVkaXJlY3QmZG9Ob3RMb2dDbGljaz10cnVl | H10: =D10*B10 -> 538
G11: Total: | H11: =SUM(H3:H10) -> 43491.2
G12: Total + Iva: | H12: =H11*1.16 -> 50449.792

Sheet 2023-12-01
A2: Descripción | B2: Cantidad | C2: Diseño | D2: Precio Público | E2: Proveedor Referencia | F2: Imagen Referencia | G2: Liga de referencia | H2: Total
A3: Computadora Dell Vostro 3710 SFF, Intel Core i7-12700 2.10GHz, 16GB, 512GB SSD, Windows 10 Pro 64-bit | B3: 1 | D3: 20739 | E3: CyberPuerta | G3: https://www.cyberpuerta.mx/Computadoras/PC-s-de-Escritorio/Computadora-Dell-Vostro-3710-SFF-Intel-Core-i7-12700-2-10GHz-16GB-512GB-SSD-Windows-10-Pro-64-bit.html?gclid=CjwKCAiAqt-dBhBcEiwATw-ggImmd4vpyh6JrYzimg3qHTRrRMLtSdeY6oqPRjrng6pfTvf_QPrVexoCZpYQAvD_BwE | H3: =D3*B3 -> 20739
A4: Computadora HP ProDesk 600 G6 SFF, Intel Core i5-10500 3.10GHz, 16GB, 1TB, Windows 10 Pro 64-bit + Teclado/Mouse | B4: 5 | D4: 16369 | E4: CyberPuerta | G4: https://www.cyberpuerta.mx/Computadoras/PC-s-de-Escritorio/Computadora-HP-ProDesk-600-G6-SFF-Intel-Core-i5-10500-3-10GHz-16GB-1TB-Windows-10-Pro-64-bit.html | H4: =D4*B4 -> 81845
A5: Monitor Dell E2223HV LED 21.4", Full HD, Widescreen, Negro | B5: 10 | D5: 1829 | E5: CyberPuerta | G5: https://www.cyberpuerta.mx/Computo-Hardware/Monitores/Monitores/Monitor-Dell-E2223HV-LED-21-4-Full-HD-Widescreen-Negro.html?gclid=CjwKCAiAqt-dBhBcEiwATw-ggC1NNcVkgkofcLtdy9SaRx7kyxb92Al9ySesbcuFrPX9mzjRQxzvrxoCj-gQAvD_BwE | H5: =D5*B5 -> 18290
A6: Cámara web 1080P con micrófono, cámara web con micrófono para PC, J JOYACCESS | B6: 6 | D6: 450.49 | E6: Amazon | G6: https://www.amazon.com.mx/micr%C3%B3fono-escritorio-videollamadas-grabaci%C3%B3n-videoconferencias/dp/B0896VS4JH/ref=sr_1_3_sspa?__mk_es_MX=%C3%85M%C3%85%C5%BD%C3%95%C3%91&crid=12KKUUD9YB76&keywords=camara%2Bweb&qid=1673121407&sprefix=camara%2Bweb%2Caps%2C142&sr=8-3-spons&spLa=ZW5jcnlwdGVkUXVhbGlmaWVyPUEzUUxNMVgyM0pTVVNOJmVuY3J5cHRlZElkPUEwNjk0NzM3MjhZR0s5U1RHQ1RWMCZlbmNyeXB0ZWRBZElkPUEwNzkyMzU4MzExM1lOSjZGQzUzUiZ3aWRnZXROYW1lPXNwX2F0ZiZhY3Rpb249Y2xpY2tSZWRpcmVjdCZkb05vdExvZ0NsaWNrPXRydWU&th=1 | H6: =D6*B6 -> 2702.94
A7: Adaptador De Red Usb Tp-link Archer T2u Plus Inalambrico /v | B7: 6 | D7: 395 | E7: Mercado Libre | G7: https://articulo.mercadolibre.com.mx/MLM-1525430103-adaptador-de-red-usb-tp-link-archer-t2u-plus-inalambrico-v-_JM#is_advertising=true&position=9&search_layout=stack&type=pad&tracking_id=06d3fbda-907c-48e7-a05a-c87fc5d58007&is_advertising=true&ad_domain=VQCATCORE_LST&ad_position=9&ad_click_id=Yjg0YTdkNTUtNjNjNi00ZWZmLWIwOTItNzlhZjg4M2RlZThj | H7: =D7*B7 -> 2370
A8: Pantalla Hisense LED Smart TV de 70 Pulgadas 4K/UHD 70H6500G con Android TV | B8: 2 | D8: 12870 | E8: Mercado Libre | G8: https://www.mercadolibre.com.mx/smart-tv-hisense-a6g-series-70a6g-lcd-4k-70-120v/p/MLM19040457?matt_tool=91188883&matt_word=&matt_source=google&matt_campaign_id=15698047816&matt_ad_group_id=143431914920&matt_match_type=&matt_network=g&matt_device=c&matt_creative=620253690614&matt_keyword=&matt_ad_position=&matt_ad_type=pla&matt_merchant_id=308851108&matt_product_id=MLM19040457-product&matt_product_partition_id=1829007894712&matt_target_id=pla-1829007894712&gclid=CjwKCAiAqt-dBhBcEiwATw-ggI4i0UI_3_ihfDwMiclVv9_8DSxql0ZlGo9MlSJgInVhPxJwyA9yYxoCct4QAvD_BwE | H8: =D8*B8 -> 25740
A9: Ghia Soporte de Piso STV-26 para Pantalla 32" - 70", hasta 25kg, Negro | B9: 2 | D9: 1679 | E9: CyberPuerta | G9: https://www.cyberpuerta.mx/Audio-y-Video/TV-y-Pantallas/Accesorios-TV/Soportes-para-Pantallas/Ghia-Soporte-de-Piso-STV-26-para-Pantalla-32-70-hasta-25kg-Negro.html | H9: =D9*B9 -> 3358
A10: Bafle Profesional Recargable Kaiser Con Tecnología Ksr-link | B10: 2 | D10: 872 | E10: Mercado Libre | G10: https://articulo.mercadolibre.com.mx/MLM-902392291-bafle-profesional-recargable-kaiser-con-tecnologia-ksr-link-_JM?matt_tool=91188883&matt_word=&matt_source=google&matt_campaign_id=15698047816&matt_ad_group_id=134599571474&matt_match_type=&matt_network=g&matt_device=c&matt_creative=571866623918&matt_keyword=&matt_ad_position=&matt_ad_type=pla&matt_merchant_id=264247105&matt_product_id=MLM902392291&matt_product_partition_id=1701193342077&matt_target_id=pla-1701193342077&gclid=CjwKCAiAqt-dBhBcEiwATw-ggDMRlE_h47Q3YAGpF2ikc-BSbNXdZlRKfNGU_GodV7Rzenqv2aelPRoC-XEQAvD_BwE | H10: =D10*B10 -> 1744
A11: No Break CyberPower CP1000AVRLCD, 600W, 1000VA, 9 Contactos | B11: 6 | D11: 3369 | E11: CyberPuerta | G11: https://www.cyberpuerta.mx/Energia/No-Break-UPS/No-Break/No-Break-CyberPower-CP1000AVRLCD-600W-1000VA-9-Contactos.html?gclid=CjwKCAiAqt-dBhBcEiwATw-ggBiGbeFd7Arg8-aL3womD6UH4tjRKaGNF0_uO682ytm07lXACuh1OhoC9fUQAvD_BwE | H11: =D11*B11 -> 20214
A12: Access Point TP-Link de Banda Dual MU-MIMO AX1800 Omada Mesh, 1775Mbit/s, 1x RJ-45, 2.4/5GHz, Antenas Internas | B12: 1 | D12: 2359 | E12: CyberPuerta | G12: https://www.cyberpuerta.mx/Hogar/Smart-Home/Smart-WiFi/Wi-Fi-en-Malla/Access-Point-TP-Link-de-Banda-Dual-MU-MIMO-AX1800-Omada-Mesh-1775Mbit-s-1x-RJ-45-2-4-5GHz-Antenas-Internas.html?gclid=CjwKCAiAqt-dBhBcEiwATw-ggKdTn-VqxeFGZifm5g4nMi51_HqpPBbBX7j1uO-KVpbqEMcm0JAGtRoCaZAQAvD_BwE | H12: =D12*B12 -> 2359
A13: TP-Link TL-WR820N Router WiFi, 2.4 GHz N 300Mbps, Multimodo, Router / Repetidor / WISP / Punto de Acceso, 2 antenas externas | B13: 1 | D13: 329.1 | E13: Amazon | G13: https://www.amazon.com.mx/TP-Link-ROUTPL900-Router-300Mbps-Tl-Wr820N/dp/B07P7S4CN1/ref=asc_df_B07P7S4CN1/?tag=gledskshopmx-20&linkCode=df0&hvadid=427127712122&hvpos=&hvnetw=g&hvrand=1196556818647332308&hvpone=&hvptwo=&hvqmt=&hvdev=c&hvdvcmdl=&hvlocint=&hvlocphy=9073959&hvtargid=pla-893491452224&th=1 | H13: =D13*B13 -> 329.1
A14: TP-Link TL-SF1048, Rack de 48 puertos, Gris | B14: 1 | D14: 2298.88 | E14: Amazon | G14: https://www.amazon.com.mx/TP-LINK-Switch-TL-SF1048-48-Puertos/dp/B003CFATU6/ref=asc_df_B003CFATU6/?tag=gledskshopmx-20&linkCode=df0&hvadid=389467214844&hvpos=&hvnetw=g&hvrand=1972945257221724829&hvpone=&hvptwo=&hvqmt=&hvdev=c&hvdvcmdl=&hvlocint=&hvlocphy=9073959&hvtargid=pla-405660646048&psc=1 | H14: =D14*B14 -> 2298.88
... A41: AOM Logitech BRIO UHD 4K Cámara Web: (960-001105) con tecnología RightLight 3 y HDR + Kit de Paquete | B41: 3 | D41: 3920.15 | E41: Amazon | G41: https://www.amazon.com.mx/C%C3%A1mara-web-Logitech-BRIO-UHD/dp/B08H8NZ5TN/ref=sr_1_27?__mk_es_MX=%C3%85M%C3%85%C5%BD%C3%95%C3%91&crid=23XGKH1QQJRY&keywords=camara+web+logitech&qid=1673127669&s=electronics&sprefix=camara+web+logitech%2Celectronics%2C114&sr=1-27&ufe=app_do%3Aamzn1.fos.2f990652-065f-4ce4-905d-4c9d6a080141 | H41: =D41*B41 -> 11760.45
H42: =D42*B42 -> 0
G43: Total: | H43: =SUM(H3:H42) -> 352888.88
H44: =H43*1.16 -> 409351.1

Sheet P2941 2024-05-27
A1: Anexo 1
A2: Descripción | B2: Cantidad | C2: Diseño | D2: Precio Público | E2: Proveedor Referencia | F2: Imagen Referencia | G2: Liga de referencia | H2: Total
A3: SSD 2.5 480GB Seagate SATA III BarraCuda 6Gb/s 7MM | B3: 2 | D3: 890 | E3: BIG COM | G3: https://bigcom.mx/producto/ssd-2-5-480gb-seagate-sata-iii-barracuda-6gb-s-7mm/?srsltid=AfmBOorVcuK0ZqL4kvA6iB4T5eCIA1YLhPVG5jRwEROQKUOogUrTqEkuuFw | H3: =D3*B3 -> 1780
A4: Rasalas 8 GB Kit DDR3 1333 MHz PC3-10600 8G PC3-10600U sin ECC sin búfer 1.5 V CL9 2RX8 Dual Rank 240 Pines UDIMM Módulo RAM de Memoria de Escritorio | B4: 5 | D4: 380 | E4: Amazon | G4: https://www.amazon.com.mx/Rasalas-Ra-8GB-10600U-Green-DBx1/dp/B07N628ZCH/ref=asc_df_B07N628ZCH/?tag=gledskshopmx-20&linkCode=df0&hvadid=698067890046&hvpos=&hvnetw=g&hvrand=1043393620137419739&hvpone=&hvptwo=&hvqmt=&hvdev=c&hvdvcmdl=&hvlocint=&hvlocphy=9073959&hvtargid=pla-791330225946&mcid=057d5f89addc37598dbf30ea3da700a4&th=1 | H4: =D4*B4 -> 1900
A5: Seagate IronWolf 4TB NAS Internal Hard Drive HDD – CMR 3.5 Inch SATA 6Gb/s 5900 RPM 64MB Cache for Raid Network Attached Storage, Rescue Services – Frustration Free Packaging (ST4000VNZ06) | B5: 3 | D5: 2900 | E5: Cyberpuerta | G5: https://www.amazon.com.mx/Seagate-IronWolf-Internal-Hard-Drive/dp/B09NHV3CK9/ref=asc_df_B09NHV3CK9/?tag=gledskshopmx-20&linkCode=df0&hvadid=629972226674&hvpos=&hvnetw=g&hvrand=13138819791445596935&hvpone=&hvptwo=&hvqmt=&hvdev=c&hvdvcmdl=&hvlocint=&hvlocphy=9073959&hvtargid=pla-1730079707966&psc=1&mcid=b3a051e960ba3bd2b1813aac17cb3936 | H5: =D5*B5 -> 8700
A6: WD Diskless My Cloud EX2 Ultra Network Attached Storage - NAS - WDBVBZ0000NCH-NESN | B6: 1 | D6: 4789 | E6: Amazon | G6: https://www.amazon.com.mx/WD-Diskless-Network-Attached-Storage/dp/B01AWH05KK/ref=asc_df_B01AWH05KK/?tag=gledskshopmx-20&linkCode=df0&hvadid=295443628737&hvpos=&hvnetw=g&hvrand=6344717820453045634&hvpone=&hvptwo=&hvqmt=&hvdev=c&hvdvcmdl=&hvlocint=&hvlocphy=9073959&hvtargid=pla-432219357336&mcid=97bd7785db0233218db09723c9d54edc&th=1 | H6: =D6*B6 -> 4789
G7: Total: | H7: =SUM(H3:H6) -> 17169
G8: Total + Iva: | H8: =H7*1.16 -> 19916.04

Sheet P2141 2023-03-27
A1: Anexo1
